2022-03-30 01:44:56 - WARNING - add_hero - Side was not specificated, randomly chosen dire
2022-03-30 01:44:56 - WARNING - add_hero - Attribute was not specificated, randomly chosen Intelligence
2022-03-30 01:44:56 - WARNING - add_hero - Power was not specificated, randomly chosen 33
2022-03-30 01:44:59 - ERROR - main - Base exception raised
Traceback (most recent call last):
  File "C:\Users\Egor\AppData\Local\Programs\Python\Python39\lib\site-packages\sqlalchemy\engine\base.py", line 3256, in _wrap_pool_connect
    return fn()
  File "C:\Users\Egor\AppData\Local\Programs\Python\Python39\lib\site-packages\sqlalchemy\pool\base.py", line 310, in connect
    return _ConnectionFairy._checkout(self)
  File "C:\Users\Egor\AppData\Local\Programs\Python\Python39\lib\site-packages\sqlalchemy\pool\base.py", line 868, in _checkout
    fairy = _ConnectionRecord.checkout(pool)
  File "C:\Users\Egor\AppData\Local\Programs\Python\Python39\lib\site-packages\sqlalchemy\pool\base.py", line 476, in checkout
    rec = pool._do_get()
  File "C:\Users\Egor\AppData\Local\Programs\Python\Python39\lib\site-packages\sqlalchemy\pool\impl.py", line 146, in _do_get
    self._dec_overflow()
  File "C:\Users\Egor\AppData\Local\Programs\Python\Python39\lib\site-packages\sqlalchemy\util\langhelpers.py", line 70, in __exit__
    compat.raise_(
  File "C:\Users\Egor\AppData\Local\Programs\Python\Python39\lib\site-packages\sqlalchemy\util\compat.py", line 207, in raise_
    raise exception
  File "C:\Users\Egor\AppData\Local\Programs\Python\Python39\lib\site-packages\sqlalchemy\pool\impl.py", line 143, in _do_get
    return self._create_connection()
  File "C:\Users\Egor\AppData\Local\Programs\Python\Python39\lib\site-packages\sqlalchemy\pool\base.py", line 256, in _create_connection
    return _ConnectionRecord(self)
  File "C:\Users\Egor\AppData\Local\Programs\Python\Python39\lib\site-packages\sqlalchemy\pool\base.py", line 371, in __init__
    self.__connect()
  File "C:\Users\Egor\AppData\Local\Programs\Python\Python39\lib\site-packages\sqlalchemy\pool\base.py", line 666, in __connect
    pool.logger.debug("Error on connect(): %s", e)
  File "C:\Users\Egor\AppData\Local\Programs\Python\Python39\lib\site-packages\sqlalchemy\util\langhelpers.py", line 70, in __exit__
    compat.raise_(
  File "C:\Users\Egor\AppData\Local\Programs\Python\Python39\lib\site-packages\sqlalchemy\util\compat.py", line 207, in raise_
    raise exception
  File "C:\Users\Egor\AppData\Local\Programs\Python\Python39\lib\site-packages\sqlalchemy\pool\base.py", line 661, in __connect
    self.dbapi_connection = connection = pool._invoke_creator(self)
  File "C:\Users\Egor\AppData\Local\Programs\Python\Python39\lib\site-packages\sqlalchemy\engine\create.py", line 590, in connect
    return dialect.connect(*cargs, **cparams)
  File "C:\Users\Egor\AppData\Local\Programs\Python\Python39\lib\site-packages\sqlalchemy\engine\default.py", line 597, in connect
    return self.dbapi.connect(*cargs, **cparams)
  File "C:\Users\Egor\AppData\Local\Programs\Python\Python39\lib\site-packages\psycopg2\__init__.py", line 122, in connect
    conn = _connect(dsn, connection_factory=connection_factory, **kwasync)
psycopg2.OperationalError: could not translate host name "db" to address: Unknown host


The above exception was the direct cause of the following exception:

Traceback (most recent call last):
  File "C:\programming\vs_code\data_school\docker_hw\scripts\scripts.py", line 120, in main
    globals()[sys.argv[1]](*sys.argv[2:])
  File "C:\programming\vs_code\data_school\docker_hw\scripts\scripts.py", line 23, in add_hero
    session.commit()
  File "C:\Users\Egor\AppData\Local\Programs\Python\Python39\lib\site-packages\sqlalchemy\orm\session.py", line 1431, in commit
    self._transaction.commit(_to_root=self.future)
  File "C:\Users\Egor\AppData\Local\Programs\Python\Python39\lib\site-packages\sqlalchemy\orm\session.py", line 829, in commit
    self._prepare_impl()
  File "C:\Users\Egor\AppData\Local\Programs\Python\Python39\lib\site-packages\sqlalchemy\orm\session.py", line 808, in _prepare_impl
    self.session.flush()
  File "C:\Users\Egor\AppData\Local\Programs\Python\Python39\lib\site-packages\sqlalchemy\orm\session.py", line 3363, in flush
    self._flush(objects)
  File "C:\Users\Egor\AppData\Local\Programs\Python\Python39\lib\site-packages\sqlalchemy\orm\session.py", line 3503, in _flush
    transaction.rollback(_capture_exception=True)
  File "C:\Users\Egor\AppData\Local\Programs\Python\Python39\lib\site-packages\sqlalchemy\util\langhelpers.py", line 70, in __exit__
    compat.raise_(
  File "C:\Users\Egor\AppData\Local\Programs\Python\Python39\lib\site-packages\sqlalchemy\util\compat.py", line 207, in raise_
    raise exception
  File "C:\Users\Egor\AppData\Local\Programs\Python\Python39\lib\site-packages\sqlalchemy\orm\session.py", line 3463, in _flush
    flush_context.execute()
  File "C:\Users\Egor\AppData\Local\Programs\Python\Python39\lib\site-packages\sqlalchemy\orm\unitofwork.py", line 456, in execute
    rec.execute(self)
  File "C:\Users\Egor\AppData\Local\Programs\Python\Python39\lib\site-packages\sqlalchemy\orm\unitofwork.py", line 630, in execute
    util.preloaded.orm_persistence.save_obj(
  File "C:\Users\Egor\AppData\Local\Programs\Python\Python39\lib\site-packages\sqlalchemy\orm\persistence.py", line 211, in save_obj
    for (
  File "C:\Users\Egor\AppData\Local\Programs\Python\Python39\lib\site-packages\sqlalchemy\orm\persistence.py", line 372, in _organize_states_for_save
    for state, dict_, mapper, connection in _connections_for_states(
  File "C:\Users\Egor\AppData\Local\Programs\Python\Python39\lib\site-packages\sqlalchemy\orm\persistence.py", line 1736, in _connections_for_states
    connection = uowtransaction.transaction.connection(base_mapper)
  File "C:\Users\Egor\AppData\Local\Programs\Python\Python39\lib\site-packages\sqlalchemy\orm\session.py", line 626, in connection
    return self._connection_for_bind(bind, execution_options)
  File "C:\Users\Egor\AppData\Local\Programs\Python\Python39\lib\site-packages\sqlalchemy\orm\session.py", line 735, in _connection_for_bind
    conn = self._parent._connection_for_bind(bind, execution_options)
  File "C:\Users\Egor\AppData\Local\Programs\Python\Python39\lib\site-packages\sqlalchemy\orm\session.py", line 747, in _connection_for_bind
    conn = bind.connect()
  File "C:\Users\Egor\AppData\Local\Programs\Python\Python39\lib\site-packages\sqlalchemy\engine\base.py", line 3210, in connect
    return self._connection_cls(self, close_with_result=close_with_result)
  File "C:\Users\Egor\AppData\Local\Programs\Python\Python39\lib\site-packages\sqlalchemy\engine\base.py", line 96, in __init__
    else engine.raw_connection()
  File "C:\Users\Egor\AppData\Local\Programs\Python\Python39\lib\site-packages\sqlalchemy\engine\base.py", line 3289, in raw_connection
    return self._wrap_pool_connect(self.pool.connect, _connection)
  File "C:\Users\Egor\AppData\Local\Programs\Python\Python39\lib\site-packages\sqlalchemy\engine\base.py", line 3259, in _wrap_pool_connect
    Connection._handle_dbapi_exception_noconnection(
  File "C:\Users\Egor\AppData\Local\Programs\Python\Python39\lib\site-packages\sqlalchemy\engine\base.py", line 2106, in _handle_dbapi_exception_noconnection
    util.raise_(
  File "C:\Users\Egor\AppData\Local\Programs\Python\Python39\lib\site-packages\sqlalchemy\util\compat.py", line 207, in raise_
    raise exception
  File "C:\Users\Egor\AppData\Local\Programs\Python\Python39\lib\site-packages\sqlalchemy\engine\base.py", line 3256, in _wrap_pool_connect
    return fn()
  File "C:\Users\Egor\AppData\Local\Programs\Python\Python39\lib\site-packages\sqlalchemy\pool\base.py", line 310, in connect
    return _ConnectionFairy._checkout(self)
  File "C:\Users\Egor\AppData\Local\Programs\Python\Python39\lib\site-packages\sqlalchemy\pool\base.py", line 868, in _checkout
    fairy = _ConnectionRecord.checkout(pool)
  File "C:\Users\Egor\AppData\Local\Programs\Python\Python39\lib\site-packages\sqlalchemy\pool\base.py", line 476, in checkout
    rec = pool._do_get()
  File "C:\Users\Egor\AppData\Local\Programs\Python\Python39\lib\site-packages\sqlalchemy\pool\impl.py", line 146, in _do_get
    self._dec_overflow()
  File "C:\Users\Egor\AppData\Local\Programs\Python\Python39\lib\site-packages\sqlalchemy\util\langhelpers.py", line 70, in __exit__
    compat.raise_(
  File "C:\Users\Egor\AppData\Local\Programs\Python\Python39\lib\site-packages\sqlalchemy\util\compat.py", line 207, in raise_
    raise exception
  File "C:\Users\Egor\AppData\Local\Programs\Python\Python39\lib\site-packages\sqlalchemy\pool\impl.py", line 143, in _do_get
    return self._create_connection()
  File "C:\Users\Egor\AppData\Local\Programs\Python\Python39\lib\site-packages\sqlalchemy\pool\base.py", line 256, in _create_connection
    return _ConnectionRecord(self)
  File "C:\Users\Egor\AppData\Local\Programs\Python\Python39\lib\site-packages\sqlalchemy\pool\base.py", line 371, in __init__
    self.__connect()
  File "C:\Users\Egor\AppData\Local\Programs\Python\Python39\lib\site-packages\sqlalchemy\pool\base.py", line 666, in __connect
    pool.logger.debug("Error on connect(): %s", e)
  File "C:\Users\Egor\AppData\Local\Programs\Python\Python39\lib\site-packages\sqlalchemy\util\langhelpers.py", line 70, in __exit__
    compat.raise_(
  File "C:\Users\Egor\AppData\Local\Programs\Python\Python39\lib\site-packages\sqlalchemy\util\compat.py", line 207, in raise_
    raise exception
  File "C:\Users\Egor\AppData\Local\Programs\Python\Python39\lib\site-packages\sqlalchemy\pool\base.py", line 661, in __connect
    self.dbapi_connection = connection = pool._invoke_creator(self)
  File "C:\Users\Egor\AppData\Local\Programs\Python\Python39\lib\site-packages\sqlalchemy\engine\create.py", line 590, in connect
    return dialect.connect(*cargs, **cparams)
  File "C:\Users\Egor\AppData\Local\Programs\Python\Python39\lib\site-packages\sqlalchemy\engine\default.py", line 597, in connect
    return self.dbapi.connect(*cargs, **cparams)
  File "C:\Users\Egor\AppData\Local\Programs\Python\Python39\lib\site-packages\psycopg2\__init__.py", line 122, in connect
    conn = _connect(dsn, connection_factory=connection_factory, **kwasync)
sqlalchemy.exc.OperationalError: (psycopg2.OperationalError) could not translate host name "db" to address: Unknown host

(Background on this error at: https://sqlalche.me/e/14/e3q8)
2022-03-30 01:48:35 - WARNING - add_hero - Side was not specificated, randomly chosen radiant
2022-03-30 01:48:35 - WARNING - add_hero - Attribute was not specificated, randomly chosen Intelligence
2022-03-30 01:48:35 - WARNING - add_hero - Power was not specificated, randomly chosen 75
2022-03-30 01:48:35 - ERROR - main - Base exception raised
Traceback (most recent call last):
  File "C:\Users\Egor\AppData\Local\Programs\Python\Python39\lib\site-packages\sqlalchemy\engine\base.py", line 1808, in _execute_context
    self.dialect.do_execute(
  File "C:\Users\Egor\AppData\Local\Programs\Python\Python39\lib\site-packages\sqlalchemy\engine\default.py", line 732, in do_execute
    cursor.execute(statement, parameters)
psycopg2.errors.UniqueViolation: ОШИБКА:  повторяющееся значение ключа нарушает ограничение уникальности "heroes_pkey"
DETAIL:  Ключ "(id)=(1)" уже существует.


The above exception was the direct cause of the following exception:

Traceback (most recent call last):
  File "C:\programming\vs_code\data_school\docker_hw\scripts\scripts.py", line 120, in main
    globals()[sys.argv[1]](*sys.argv[2:])
  File "C:\programming\vs_code\data_school\docker_hw\scripts\scripts.py", line 23, in add_hero
    session.commit()
  File "C:\Users\Egor\AppData\Local\Programs\Python\Python39\lib\site-packages\sqlalchemy\orm\session.py", line 1431, in commit
    self._transaction.commit(_to_root=self.future)
  File "C:\Users\Egor\AppData\Local\Programs\Python\Python39\lib\site-packages\sqlalchemy\orm\session.py", line 829, in commit
    self._prepare_impl()
  File "C:\Users\Egor\AppData\Local\Programs\Python\Python39\lib\site-packages\sqlalchemy\orm\session.py", line 808, in _prepare_impl
    self.session.flush()
  File "C:\Users\Egor\AppData\Local\Programs\Python\Python39\lib\site-packages\sqlalchemy\orm\session.py", line 3363, in flush
    self._flush(objects)
  File "C:\Users\Egor\AppData\Local\Programs\Python\Python39\lib\site-packages\sqlalchemy\orm\session.py", line 3503, in _flush
    transaction.rollback(_capture_exception=True)
  File "C:\Users\Egor\AppData\Local\Programs\Python\Python39\lib\site-packages\sqlalchemy\util\langhelpers.py", line 70, in __exit__
    compat.raise_(
  File "C:\Users\Egor\AppData\Local\Programs\Python\Python39\lib\site-packages\sqlalchemy\util\compat.py", line 207, in raise_
    raise exception
  File "C:\Users\Egor\AppData\Local\Programs\Python\Python39\lib\site-packages\sqlalchemy\orm\session.py", line 3463, in _flush
    flush_context.execute()
  File "C:\Users\Egor\AppData\Local\Programs\Python\Python39\lib\site-packages\sqlalchemy\orm\unitofwork.py", line 456, in execute
    rec.execute(self)
  File "C:\Users\Egor\AppData\Local\Programs\Python\Python39\lib\site-packages\sqlalchemy\orm\unitofwork.py", line 630, in execute
    util.preloaded.orm_persistence.save_obj(
  File "C:\Users\Egor\AppData\Local\Programs\Python\Python39\lib\site-packages\sqlalchemy\orm\persistence.py", line 244, in save_obj
    _emit_insert_statements(
  File "C:\Users\Egor\AppData\Local\Programs\Python\Python39\lib\site-packages\sqlalchemy\orm\persistence.py", line 1237, in _emit_insert_statements
    result = connection._execute_20(
  File "C:\Users\Egor\AppData\Local\Programs\Python\Python39\lib\site-packages\sqlalchemy\engine\base.py", line 1620, in _execute_20
    return meth(self, args_10style, kwargs_10style, execution_options)
  File "C:\Users\Egor\AppData\Local\Programs\Python\Python39\lib\site-packages\sqlalchemy\sql\elements.py", line 325, in _execute_on_connection
    return connection._execute_clauseelement(
  File "C:\Users\Egor\AppData\Local\Programs\Python\Python39\lib\site-packages\sqlalchemy\engine\base.py", line 1487, in _execute_clauseelement
    ret = self._execute_context(
  File "C:\Users\Egor\AppData\Local\Programs\Python\Python39\lib\site-packages\sqlalchemy\engine\base.py", line 1851, in _execute_context
    self._handle_dbapi_exception(
  File "C:\Users\Egor\AppData\Local\Programs\Python\Python39\lib\site-packages\sqlalchemy\engine\base.py", line 2032, in _handle_dbapi_exception
    util.raise_(
  File "C:\Users\Egor\AppData\Local\Programs\Python\Python39\lib\site-packages\sqlalchemy\util\compat.py", line 207, in raise_
    raise exception
  File "C:\Users\Egor\AppData\Local\Programs\Python\Python39\lib\site-packages\sqlalchemy\engine\base.py", line 1808, in _execute_context
    self.dialect.do_execute(
  File "C:\Users\Egor\AppData\Local\Programs\Python\Python39\lib\site-packages\sqlalchemy\engine\default.py", line 732, in do_execute
    cursor.execute(statement, parameters)
sqlalchemy.exc.IntegrityError: (psycopg2.errors.UniqueViolation) ОШИБКА:  повторяющееся значение ключа нарушает ограничение уникальности "heroes_pkey"
DETAIL:  Ключ "(id)=(1)" уже существует.

[SQL: INSERT INTO heroes (side, name, birthday, attribute, power) VALUES (%(side)s, %(name)s, %(birthday)s, %(attribute)s, %(power)s) RETURNING heroes.id]
[parameters: {'side': 'radiant', 'name': 'axet', 'birthday': None, 'attribute': 'Intelligence', 'power': 75}]
(Background on this error at: https://sqlalche.me/e/14/gkpj)
2022-03-30 01:49:56 - WARNING - add_hero - Side was not specificated, randomly chosen dire
2022-03-30 01:49:56 - WARNING - add_hero - Attribute was not specificated, randomly chosen Agility
2022-03-30 01:49:56 - WARNING - add_hero - Power was not specificated, randomly chosen 98
2022-03-30 01:49:56 - ERROR - main - Base exception raised
Traceback (most recent call last):
  File "C:\Users\Egor\AppData\Local\Programs\Python\Python39\lib\site-packages\sqlalchemy\engine\base.py", line 1808, in _execute_context
    self.dialect.do_execute(
  File "C:\Users\Egor\AppData\Local\Programs\Python\Python39\lib\site-packages\sqlalchemy\engine\default.py", line 732, in do_execute
    cursor.execute(statement, parameters)
psycopg2.errors.UniqueViolation: ОШИБКА:  повторяющееся значение ключа нарушает ограничение уникальности "heroes_pkey"
DETAIL:  Ключ "(id)=(1)" уже существует.


The above exception was the direct cause of the following exception:

Traceback (most recent call last):
  File "C:\programming\vs_code\data_school\docker_hw\scripts\scripts.py", line 120, in main
    globals()[sys.argv[1]](*sys.argv[2:])
  File "C:\programming\vs_code\data_school\docker_hw\scripts\scripts.py", line 23, in add_hero
    session.commit()
  File "C:\Users\Egor\AppData\Local\Programs\Python\Python39\lib\site-packages\sqlalchemy\orm\session.py", line 1431, in commit
    self._transaction.commit(_to_root=self.future)
  File "C:\Users\Egor\AppData\Local\Programs\Python\Python39\lib\site-packages\sqlalchemy\orm\session.py", line 829, in commit
    self._prepare_impl()
  File "C:\Users\Egor\AppData\Local\Programs\Python\Python39\lib\site-packages\sqlalchemy\orm\session.py", line 808, in _prepare_impl
    self.session.flush()
  File "C:\Users\Egor\AppData\Local\Programs\Python\Python39\lib\site-packages\sqlalchemy\orm\session.py", line 3363, in flush
    self._flush(objects)
  File "C:\Users\Egor\AppData\Local\Programs\Python\Python39\lib\site-packages\sqlalchemy\orm\session.py", line 3503, in _flush
    transaction.rollback(_capture_exception=True)
  File "C:\Users\Egor\AppData\Local\Programs\Python\Python39\lib\site-packages\sqlalchemy\util\langhelpers.py", line 70, in __exit__
    compat.raise_(
  File "C:\Users\Egor\AppData\Local\Programs\Python\Python39\lib\site-packages\sqlalchemy\util\compat.py", line 207, in raise_
    raise exception
  File "C:\Users\Egor\AppData\Local\Programs\Python\Python39\lib\site-packages\sqlalchemy\orm\session.py", line 3463, in _flush
    flush_context.execute()
  File "C:\Users\Egor\AppData\Local\Programs\Python\Python39\lib\site-packages\sqlalchemy\orm\unitofwork.py", line 456, in execute
    rec.execute(self)
  File "C:\Users\Egor\AppData\Local\Programs\Python\Python39\lib\site-packages\sqlalchemy\orm\unitofwork.py", line 630, in execute
    util.preloaded.orm_persistence.save_obj(
  File "C:\Users\Egor\AppData\Local\Programs\Python\Python39\lib\site-packages\sqlalchemy\orm\persistence.py", line 244, in save_obj
    _emit_insert_statements(
  File "C:\Users\Egor\AppData\Local\Programs\Python\Python39\lib\site-packages\sqlalchemy\orm\persistence.py", line 1237, in _emit_insert_statements
    result = connection._execute_20(
  File "C:\Users\Egor\AppData\Local\Programs\Python\Python39\lib\site-packages\sqlalchemy\engine\base.py", line 1620, in _execute_20
    return meth(self, args_10style, kwargs_10style, execution_options)
  File "C:\Users\Egor\AppData\Local\Programs\Python\Python39\lib\site-packages\sqlalchemy\sql\elements.py", line 325, in _execute_on_connection
    return connection._execute_clauseelement(
  File "C:\Users\Egor\AppData\Local\Programs\Python\Python39\lib\site-packages\sqlalchemy\engine\base.py", line 1487, in _execute_clauseelement
    ret = self._execute_context(
  File "C:\Users\Egor\AppData\Local\Programs\Python\Python39\lib\site-packages\sqlalchemy\engine\base.py", line 1851, in _execute_context
    self._handle_dbapi_exception(
  File "C:\Users\Egor\AppData\Local\Programs\Python\Python39\lib\site-packages\sqlalchemy\engine\base.py", line 2032, in _handle_dbapi_exception
    util.raise_(
  File "C:\Users\Egor\AppData\Local\Programs\Python\Python39\lib\site-packages\sqlalchemy\util\compat.py", line 207, in raise_
    raise exception
  File "C:\Users\Egor\AppData\Local\Programs\Python\Python39\lib\site-packages\sqlalchemy\engine\base.py", line 1808, in _execute_context
    self.dialect.do_execute(
  File "C:\Users\Egor\AppData\Local\Programs\Python\Python39\lib\site-packages\sqlalchemy\engine\default.py", line 732, in do_execute
    cursor.execute(statement, parameters)
sqlalchemy.exc.IntegrityError: (psycopg2.errors.UniqueViolation) ОШИБКА:  повторяющееся значение ключа нарушает ограничение уникальности "heroes_pkey"
DETAIL:  Ключ "(id)=(1)" уже существует.

[SQL: INSERT INTO heroes (side, name, birthday, attribute, power) VALUES (%(side)s, %(name)s, %(birthday)s, %(attribute)s, %(power)s) RETURNING heroes.id]
[parameters: {'side': 'dire', 'name': 'axe', 'birthday': None, 'attribute': 'Agility', 'power': 98}]
(Background on this error at: https://sqlalche.me/e/14/gkpj)
2022-03-30 01:50:19 - WARNING - add_hero - Side was not specificated, randomly chosen dire
2022-03-30 01:50:19 - WARNING - add_hero - Attribute was not specificated, randomly chosen Strength
2022-03-30 01:50:19 - WARNING - add_hero - Power was not specificated, randomly chosen 78
2022-03-30 01:50:19 - ERROR - main - Base exception raised
Traceback (most recent call last):
  File "C:\Users\Egor\AppData\Local\Programs\Python\Python39\lib\site-packages\sqlalchemy\engine\base.py", line 1808, in _execute_context
    self.dialect.do_execute(
  File "C:\Users\Egor\AppData\Local\Programs\Python\Python39\lib\site-packages\sqlalchemy\engine\default.py", line 732, in do_execute
    cursor.execute(statement, parameters)
psycopg2.errors.UniqueViolation: ОШИБКА:  повторяющееся значение ключа нарушает ограничение уникальности "heroes_pkey"
DETAIL:  Ключ "(id)=(2)" уже существует.


The above exception was the direct cause of the following exception:

Traceback (most recent call last):
  File "C:\programming\vs_code\data_school\docker_hw\scripts\scripts.py", line 120, in main
    globals()[sys.argv[1]](*sys.argv[2:])
  File "C:\programming\vs_code\data_school\docker_hw\scripts\scripts.py", line 23, in add_hero
    session.commit()
  File "C:\Users\Egor\AppData\Local\Programs\Python\Python39\lib\site-packages\sqlalchemy\orm\session.py", line 1431, in commit
    self._transaction.commit(_to_root=self.future)
  File "C:\Users\Egor\AppData\Local\Programs\Python\Python39\lib\site-packages\sqlalchemy\orm\session.py", line 829, in commit
    self._prepare_impl()
  File "C:\Users\Egor\AppData\Local\Programs\Python\Python39\lib\site-packages\sqlalchemy\orm\session.py", line 808, in _prepare_impl
    self.session.flush()
  File "C:\Users\Egor\AppData\Local\Programs\Python\Python39\lib\site-packages\sqlalchemy\orm\session.py", line 3363, in flush
    self._flush(objects)
  File "C:\Users\Egor\AppData\Local\Programs\Python\Python39\lib\site-packages\sqlalchemy\orm\session.py", line 3503, in _flush
    transaction.rollback(_capture_exception=True)
  File "C:\Users\Egor\AppData\Local\Programs\Python\Python39\lib\site-packages\sqlalchemy\util\langhelpers.py", line 70, in __exit__
    compat.raise_(
  File "C:\Users\Egor\AppData\Local\Programs\Python\Python39\lib\site-packages\sqlalchemy\util\compat.py", line 207, in raise_
    raise exception
  File "C:\Users\Egor\AppData\Local\Programs\Python\Python39\lib\site-packages\sqlalchemy\orm\session.py", line 3463, in _flush
    flush_context.execute()
  File "C:\Users\Egor\AppData\Local\Programs\Python\Python39\lib\site-packages\sqlalchemy\orm\unitofwork.py", line 456, in execute
    rec.execute(self)
  File "C:\Users\Egor\AppData\Local\Programs\Python\Python39\lib\site-packages\sqlalchemy\orm\unitofwork.py", line 630, in execute
    util.preloaded.orm_persistence.save_obj(
  File "C:\Users\Egor\AppData\Local\Programs\Python\Python39\lib\site-packages\sqlalchemy\orm\persistence.py", line 244, in save_obj
    _emit_insert_statements(
  File "C:\Users\Egor\AppData\Local\Programs\Python\Python39\lib\site-packages\sqlalchemy\orm\persistence.py", line 1237, in _emit_insert_statements
    result = connection._execute_20(
  File "C:\Users\Egor\AppData\Local\Programs\Python\Python39\lib\site-packages\sqlalchemy\engine\base.py", line 1620, in _execute_20
    return meth(self, args_10style, kwargs_10style, execution_options)
  File "C:\Users\Egor\AppData\Local\Programs\Python\Python39\lib\site-packages\sqlalchemy\sql\elements.py", line 325, in _execute_on_connection
    return connection._execute_clauseelement(
  File "C:\Users\Egor\AppData\Local\Programs\Python\Python39\lib\site-packages\sqlalchemy\engine\base.py", line 1487, in _execute_clauseelement
    ret = self._execute_context(
  File "C:\Users\Egor\AppData\Local\Programs\Python\Python39\lib\site-packages\sqlalchemy\engine\base.py", line 1851, in _execute_context
    self._handle_dbapi_exception(
  File "C:\Users\Egor\AppData\Local\Programs\Python\Python39\lib\site-packages\sqlalchemy\engine\base.py", line 2032, in _handle_dbapi_exception
    util.raise_(
  File "C:\Users\Egor\AppData\Local\Programs\Python\Python39\lib\site-packages\sqlalchemy\util\compat.py", line 207, in raise_
    raise exception
  File "C:\Users\Egor\AppData\Local\Programs\Python\Python39\lib\site-packages\sqlalchemy\engine\base.py", line 1808, in _execute_context
    self.dialect.do_execute(
  File "C:\Users\Egor\AppData\Local\Programs\Python\Python39\lib\site-packages\sqlalchemy\engine\default.py", line 732, in do_execute
    cursor.execute(statement, parameters)
sqlalchemy.exc.IntegrityError: (psycopg2.errors.UniqueViolation) ОШИБКА:  повторяющееся значение ключа нарушает ограничение уникальности "heroes_pkey"
DETAIL:  Ключ "(id)=(2)" уже существует.

[SQL: INSERT INTO heroes (side, name, birthday, attribute, power) VALUES (%(side)s, %(name)s, %(birthday)s, %(attribute)s, %(power)s) RETURNING heroes.id]
[parameters: {'side': 'dire', 'name': 'axe', 'birthday': None, 'attribute': 'Strength', 'power': 78}]
(Background on this error at: https://sqlalche.me/e/14/gkpj)
2022-03-30 01:51:42 - WARNING - add_hero - Side was not specificated, randomly chosen radiant
2022-03-30 01:51:42 - WARNING - add_hero - Attribute was not specificated, randomly chosen Agility
2022-03-30 01:51:42 - WARNING - add_hero - Power was not specificated, randomly chosen 63
2022-03-30 01:51:42 - ERROR - main - Base exception raised
Traceback (most recent call last):
  File "C:\Users\Egor\AppData\Local\Programs\Python\Python39\lib\site-packages\sqlalchemy\engine\base.py", line 1808, in _execute_context
    self.dialect.do_execute(
  File "C:\Users\Egor\AppData\Local\Programs\Python\Python39\lib\site-packages\sqlalchemy\engine\default.py", line 732, in do_execute
    cursor.execute(statement, parameters)
psycopg2.errors.UniqueViolation: ОШИБКА:  повторяющееся значение ключа нарушает ограничение уникальности "heroes_pkey"
DETAIL:  Ключ "(id)=(3)" уже существует.


The above exception was the direct cause of the following exception:

Traceback (most recent call last):
  File "C:\programming\vs_code\data_school\docker_hw\scripts\scripts.py", line 121, in main
    globals()[sys.argv[1]](*sys.argv[2:])
  File "C:\programming\vs_code\data_school\docker_hw\scripts\scripts.py", line 23, in add_hero
    session.commit()
  File "C:\Users\Egor\AppData\Local\Programs\Python\Python39\lib\site-packages\sqlalchemy\orm\session.py", line 1431, in commit
    self._transaction.commit(_to_root=self.future)
  File "C:\Users\Egor\AppData\Local\Programs\Python\Python39\lib\site-packages\sqlalchemy\orm\session.py", line 829, in commit
    self._prepare_impl()
  File "C:\Users\Egor\AppData\Local\Programs\Python\Python39\lib\site-packages\sqlalchemy\orm\session.py", line 808, in _prepare_impl
    self.session.flush()
  File "C:\Users\Egor\AppData\Local\Programs\Python\Python39\lib\site-packages\sqlalchemy\orm\session.py", line 3363, in flush
    self._flush(objects)
  File "C:\Users\Egor\AppData\Local\Programs\Python\Python39\lib\site-packages\sqlalchemy\orm\session.py", line 3503, in _flush
    transaction.rollback(_capture_exception=True)
  File "C:\Users\Egor\AppData\Local\Programs\Python\Python39\lib\site-packages\sqlalchemy\util\langhelpers.py", line 70, in __exit__
    compat.raise_(
  File "C:\Users\Egor\AppData\Local\Programs\Python\Python39\lib\site-packages\sqlalchemy\util\compat.py", line 207, in raise_
    raise exception
  File "C:\Users\Egor\AppData\Local\Programs\Python\Python39\lib\site-packages\sqlalchemy\orm\session.py", line 3463, in _flush
    flush_context.execute()
  File "C:\Users\Egor\AppData\Local\Programs\Python\Python39\lib\site-packages\sqlalchemy\orm\unitofwork.py", line 456, in execute
    rec.execute(self)
  File "C:\Users\Egor\AppData\Local\Programs\Python\Python39\lib\site-packages\sqlalchemy\orm\unitofwork.py", line 630, in execute
    util.preloaded.orm_persistence.save_obj(
  File "C:\Users\Egor\AppData\Local\Programs\Python\Python39\lib\site-packages\sqlalchemy\orm\persistence.py", line 244, in save_obj
    _emit_insert_statements(
  File "C:\Users\Egor\AppData\Local\Programs\Python\Python39\lib\site-packages\sqlalchemy\orm\persistence.py", line 1237, in _emit_insert_statements
    result = connection._execute_20(
  File "C:\Users\Egor\AppData\Local\Programs\Python\Python39\lib\site-packages\sqlalchemy\engine\base.py", line 1620, in _execute_20
    return meth(self, args_10style, kwargs_10style, execution_options)
  File "C:\Users\Egor\AppData\Local\Programs\Python\Python39\lib\site-packages\sqlalchemy\sql\elements.py", line 325, in _execute_on_connection
    return connection._execute_clauseelement(
  File "C:\Users\Egor\AppData\Local\Programs\Python\Python39\lib\site-packages\sqlalchemy\engine\base.py", line 1487, in _execute_clauseelement
    ret = self._execute_context(
  File "C:\Users\Egor\AppData\Local\Programs\Python\Python39\lib\site-packages\sqlalchemy\engine\base.py", line 1851, in _execute_context
    self._handle_dbapi_exception(
  File "C:\Users\Egor\AppData\Local\Programs\Python\Python39\lib\site-packages\sqlalchemy\engine\base.py", line 2032, in _handle_dbapi_exception
    util.raise_(
  File "C:\Users\Egor\AppData\Local\Programs\Python\Python39\lib\site-packages\sqlalchemy\util\compat.py", line 207, in raise_
    raise exception
  File "C:\Users\Egor\AppData\Local\Programs\Python\Python39\lib\site-packages\sqlalchemy\engine\base.py", line 1808, in _execute_context
    self.dialect.do_execute(
  File "C:\Users\Egor\AppData\Local\Programs\Python\Python39\lib\site-packages\sqlalchemy\engine\default.py", line 732, in do_execute
    cursor.execute(statement, parameters)
sqlalchemy.exc.IntegrityError: (psycopg2.errors.UniqueViolation) ОШИБКА:  повторяющееся значение ключа нарушает ограничение уникальности "heroes_pkey"
DETAIL:  Ключ "(id)=(3)" уже существует.

[SQL: INSERT INTO heroes (side, name, birthday, attribute, power) VALUES (%(side)s, %(name)s, %(birthday)s, %(attribute)s, %(power)s) RETURNING heroes.id]
[parameters: {'side': 'radiant', 'name': 'axe', 'birthday': None, 'attribute': 'Agility', 'power': 63}]
(Background on this error at: https://sqlalche.me/e/14/gkpj)
2022-03-30 01:52:01 - WARNING - add_hero - Side was not specificated, randomly chosen radiant
2022-03-30 01:52:01 - WARNING - add_hero - Attribute was not specificated, randomly chosen Intelligence
2022-03-30 01:52:01 - WARNING - add_hero - Power was not specificated, randomly chosen 9
2022-03-30 01:52:01 - ERROR - main - Base exception raised
Traceback (most recent call last):
  File "C:\Users\Egor\AppData\Local\Programs\Python\Python39\lib\site-packages\sqlalchemy\engine\base.py", line 1808, in _execute_context
    self.dialect.do_execute(
  File "C:\Users\Egor\AppData\Local\Programs\Python\Python39\lib\site-packages\sqlalchemy\engine\default.py", line 732, in do_execute
    cursor.execute(statement, parameters)
psycopg2.errors.UniqueViolation: ОШИБКА:  повторяющееся значение ключа нарушает ограничение уникальности "heroes_pkey"
DETAIL:  Ключ "(id)=(1)" уже существует.


The above exception was the direct cause of the following exception:

Traceback (most recent call last):
  File "C:\programming\vs_code\data_school\docker_hw\scripts\scripts.py", line 121, in main
    globals()[sys.argv[1]](*sys.argv[2:])
  File "C:\programming\vs_code\data_school\docker_hw\scripts\scripts.py", line 23, in add_hero
    session.commit()
  File "C:\Users\Egor\AppData\Local\Programs\Python\Python39\lib\site-packages\sqlalchemy\orm\session.py", line 1431, in commit
    self._transaction.commit(_to_root=self.future)
  File "C:\Users\Egor\AppData\Local\Programs\Python\Python39\lib\site-packages\sqlalchemy\orm\session.py", line 829, in commit
    self._prepare_impl()
  File "C:\Users\Egor\AppData\Local\Programs\Python\Python39\lib\site-packages\sqlalchemy\orm\session.py", line 808, in _prepare_impl
    self.session.flush()
  File "C:\Users\Egor\AppData\Local\Programs\Python\Python39\lib\site-packages\sqlalchemy\orm\session.py", line 3363, in flush
    self._flush(objects)
  File "C:\Users\Egor\AppData\Local\Programs\Python\Python39\lib\site-packages\sqlalchemy\orm\session.py", line 3503, in _flush
    transaction.rollback(_capture_exception=True)
  File "C:\Users\Egor\AppData\Local\Programs\Python\Python39\lib\site-packages\sqlalchemy\util\langhelpers.py", line 70, in __exit__
    compat.raise_(
  File "C:\Users\Egor\AppData\Local\Programs\Python\Python39\lib\site-packages\sqlalchemy\util\compat.py", line 207, in raise_
    raise exception
  File "C:\Users\Egor\AppData\Local\Programs\Python\Python39\lib\site-packages\sqlalchemy\orm\session.py", line 3463, in _flush
    flush_context.execute()
  File "C:\Users\Egor\AppData\Local\Programs\Python\Python39\lib\site-packages\sqlalchemy\orm\unitofwork.py", line 456, in execute
    rec.execute(self)
  File "C:\Users\Egor\AppData\Local\Programs\Python\Python39\lib\site-packages\sqlalchemy\orm\unitofwork.py", line 630, in execute
    util.preloaded.orm_persistence.save_obj(
  File "C:\Users\Egor\AppData\Local\Programs\Python\Python39\lib\site-packages\sqlalchemy\orm\persistence.py", line 244, in save_obj
    _emit_insert_statements(
  File "C:\Users\Egor\AppData\Local\Programs\Python\Python39\lib\site-packages\sqlalchemy\orm\persistence.py", line 1237, in _emit_insert_statements
    result = connection._execute_20(
  File "C:\Users\Egor\AppData\Local\Programs\Python\Python39\lib\site-packages\sqlalchemy\engine\base.py", line 1620, in _execute_20
    return meth(self, args_10style, kwargs_10style, execution_options)
  File "C:\Users\Egor\AppData\Local\Programs\Python\Python39\lib\site-packages\sqlalchemy\sql\elements.py", line 325, in _execute_on_connection
    return connection._execute_clauseelement(
  File "C:\Users\Egor\AppData\Local\Programs\Python\Python39\lib\site-packages\sqlalchemy\engine\base.py", line 1487, in _execute_clauseelement
    ret = self._execute_context(
  File "C:\Users\Egor\AppData\Local\Programs\Python\Python39\lib\site-packages\sqlalchemy\engine\base.py", line 1851, in _execute_context
    self._handle_dbapi_exception(
  File "C:\Users\Egor\AppData\Local\Programs\Python\Python39\lib\site-packages\sqlalchemy\engine\base.py", line 2032, in _handle_dbapi_exception
    util.raise_(
  File "C:\Users\Egor\AppData\Local\Programs\Python\Python39\lib\site-packages\sqlalchemy\util\compat.py", line 207, in raise_
    raise exception
  File "C:\Users\Egor\AppData\Local\Programs\Python\Python39\lib\site-packages\sqlalchemy\engine\base.py", line 1808, in _execute_context
    self.dialect.do_execute(
  File "C:\Users\Egor\AppData\Local\Programs\Python\Python39\lib\site-packages\sqlalchemy\engine\default.py", line 732, in do_execute
    cursor.execute(statement, parameters)
sqlalchemy.exc.IntegrityError: (psycopg2.errors.UniqueViolation) ОШИБКА:  повторяющееся значение ключа нарушает ограничение уникальности "heroes_pkey"
DETAIL:  Ключ "(id)=(1)" уже существует.

[SQL: INSERT INTO heroes (side, name, birthday, attribute, power) VALUES (%(side)s, %(name)s, %(birthday)s, %(attribute)s, %(power)s) RETURNING heroes.id]
[parameters: {'side': 'radiant', 'name': 'axe', 'birthday': None, 'attribute': 'Intelligence', 'power': 9}]
(Background on this error at: https://sqlalche.me/e/14/gkpj)
2022-03-30 01:58:37 - WARNING - add_hero - Side was not specificated, randomly chosen dire
2022-03-30 01:58:37 - WARNING - add_hero - Attribute was not specificated, randomly chosen Agility
2022-03-30 01:58:37 - WARNING - add_hero - Power was not specificated, randomly chosen 76
2022-03-30 01:58:38 - INFO - add_hero - Hero axe has been added for dire side
